<?xml version="1.0" encoding="utf-8"?>
<!-- =================================================================================== -->
<!-- |    This document was autogenerated by xacro from imu.urdf.xacro                 | -->
<!-- |    EDITING THIS FILE BY HAND IS NOT RECOMMENDED                                 | -->
<!-- =================================================================================== -->
<robot name="imu">
  <link name="world"/>
  <joint name="imu_to_world0_est" type="floating">
    <parent link="world"/>
    <child link="imu_link0_est"/>
    <!-- XYZ, RPY from parent Visual Origin (Center o Gravity) -->
    <!-- in this case it's 0 0 0-->
    <origin rpy="0 0 0" xyz="0 0 0"/>
  </joint>
  <link name="imu_link0_est">
    <inertial>
      <origin rpy="0 0 0" xyz="0 0 0.005"/>
      <mass value="0.01"/>
      <inertia ixx="0.0" ixy="0.0" ixz="0.0" iyy="0.0" iyz="0.0" izz="0.0"/>
    </inertial>
    <visual>
      <origin rpy="0 0 0" xyz="0 0 0.005"/>
      <geometry>
        <box size="0.02 0.02 0.01"/>
      </geometry>
    </visual>
  </link>
  <gazebo reference="imu_link0_est">
    <material>Gazebo/White</material>
    <gravity>false</gravity>
    <sensor name="imu_sensor0_est" type="imu">
      <always_on>true</always_on>
      <update_rate>100</update_rate>
      <visualize>true</visualize>
      <topic>imu_data0_est</topic>
      <plugin filename="libgazebo_ros_imu_sensor.so" name="imu_plugin">
        <topicName>imu_data0_est</topicName>
        <bodyName>imu_link0_est</bodyName>
        <updateRateHZ>100.0</updateRateHZ>
        <gaussianNoise>0.0</gaussianNoise>
        <xyzOffset>0.0 0.0 0.0</xyzOffset>
        <rpyOffset>0 0 0</rpyOffset>
        <frameName>imu_link0_est</frameName>
      </plugin>
      <pose>0 0 0 0 0 0</pose>
    </sensor>
  </gazebo>
  <joint name="imu_to_world1_est" type="floating">
    <parent link="world"/>
    <child link="imu_link1_est"/>
    <!-- XYZ, RPY from parent Visual Origin (Center o Gravity) -->
    <!-- in this case it's 0 0 0-->
    <origin rpy="0 0 0" xyz="0 0 0"/>
  </joint>
  <link name="imu_link1_est">
    <inertial>
      <origin rpy="0 0 0" xyz="0 0 0.005"/>
      <mass value="0.01"/>
      <inertia ixx="0.0" ixy="0.0" ixz="0.0" iyy="0.0" iyz="0.0" izz="0.0"/>
    </inertial>
    <visual>
      <origin rpy="0 0 0" xyz="0 0 0.005"/>
      <geometry>
        <box size="0.02 0.02 0.01"/>
      </geometry>
    </visual>
  </link>
  <gazebo reference="imu_link1_est">
    <material>Gazebo/White</material>
    <gravity>false</gravity>
    <sensor name="imu_sensor1_est" type="imu">
      <always_on>true</always_on>
      <update_rate>100</update_rate>
      <visualize>true</visualize>
      <topic>imu_data1_est</topic>
      <plugin filename="libgazebo_ros_imu_sensor.so" name="imu_plugin">
        <topicName>imu_data1_est</topicName>
        <bodyName>imu_link1_est</bodyName>
        <updateRateHZ>100.0</updateRateHZ>
        <gaussianNoise>0.0</gaussianNoise>
        <xyzOffset>0.0 0.0 0.0</xyzOffset>
        <rpyOffset>0 0 0</rpyOffset>
        <frameName>imu_link1_est</frameName>
      </plugin>
      <pose>0 0 0 0 0 0</pose>
    </sensor>
  </gazebo>
  <joint name="imu_to_world2_est" type="floating">
    <parent link="world"/>
    <child link="imu_link2_est"/>
    <!-- XYZ, RPY from parent Visual Origin (Center o Gravity) -->
    <!-- in this case it's 0 0 0-->
    <origin rpy="0 0 0" xyz="0 0 0"/>
  </joint>
  <link name="imu_link2_est">
    <inertial>
      <origin rpy="0 0 0" xyz="0 0 0.005"/>
      <mass value="0.01"/>
      <inertia ixx="0.0" ixy="0.0" ixz="0.0" iyy="0.0" iyz="0.0" izz="0.0"/>
    </inertial>
    <visual>
      <origin rpy="0 0 0" xyz="0 0 0.005"/>
      <geometry>
        <box size="0.02 0.02 0.01"/>
      </geometry>
    </visual>
  </link>
  <gazebo reference="imu_link2_est">
    <material>Gazebo/White</material>
    <gravity>false</gravity>
    <sensor name="imu_sensor2_est" type="imu">
      <always_on>true</always_on>
      <update_rate>100</update_rate>
      <visualize>true</visualize>
      <topic>imu_data2_est</topic>
      <plugin filename="libgazebo_ros_imu_sensor.so" name="imu_plugin">
        <topicName>imu_data2_est</topicName>
        <bodyName>imu_link2_est</bodyName>
        <updateRateHZ>100.0</updateRateHZ>
        <gaussianNoise>0.0</gaussianNoise>
        <xyzOffset>0.0 0.0 0.0</xyzOffset>
        <rpyOffset>0 0 0</rpyOffset>
        <frameName>imu_link2_est</frameName>
      </plugin>
      <pose>0 0 0 0 0 0</pose>
    </sensor>
  </gazebo>
  <joint name="imu_to_world3_est" type="floating">
    <parent link="world"/>
    <child link="imu_link3_est"/>
    <!-- XYZ, RPY from parent Visual Origin (Center o Gravity) -->
    <!-- in this case it's 0 0 0-->
    <origin rpy="0 0 0" xyz="0 0 0"/>
  </joint>
  <link name="imu_link3_est">
    <inertial>
      <origin rpy="0 0 0" xyz="0 0 0.005"/>
      <mass value="0.01"/>
      <inertia ixx="0.0" ixy="0.0" ixz="0.0" iyy="0.0" iyz="0.0" izz="0.0"/>
    </inertial>
    <visual>
      <origin rpy="0 0 0" xyz="0 0 0.005"/>
      <geometry>
        <box size="0.02 0.02 0.01"/>
      </geometry>
    </visual>
  </link>
  <gazebo reference="imu_link3_est">
    <material>Gazebo/White</material>
    <gravity>false</gravity>
    <sensor name="imu_sensor3_est" type="imu">
      <always_on>true</always_on>
      <update_rate>100</update_rate>
      <visualize>true</visualize>
      <topic>imu_data3_est</topic>
      <plugin filename="libgazebo_ros_imu_sensor.so" name="imu_plugin">
        <topicName>imu_data3_est</topicName>
        <bodyName>imu_link3_est</bodyName>
        <updateRateHZ>100.0</updateRateHZ>
        <gaussianNoise>0.0</gaussianNoise>
        <xyzOffset>0.0 0.0 0.0</xyzOffset>
        <rpyOffset>0 0 0</rpyOffset>
        <frameName>imu_link3_est</frameName>
      </plugin>
      <pose>0 0 0 0 0 0</pose>
    </sensor>
  </gazebo>
  <joint name="imu_to_world4_est" type="floating">
    <parent link="world"/>
    <child link="imu_link4_est"/>
    <!-- XYZ, RPY from parent Visual Origin (Center o Gravity) -->
    <!-- in this case it's 0 0 0-->
    <origin rpy="0 0 0" xyz="0 0 0"/>
  </joint>
  <link name="imu_link4_est">
    <inertial>
      <origin rpy="0 0 0" xyz="0 0 0.005"/>
      <mass value="0.01"/>
      <inertia ixx="0.0" ixy="0.0" ixz="0.0" iyy="0.0" iyz="0.0" izz="0.0"/>
    </inertial>
    <visual>
      <origin rpy="0 0 0" xyz="0 0 0.005"/>
      <geometry>
        <box size="0.02 0.02 0.01"/>
      </geometry>
    </visual>
  </link>
  <gazebo reference="imu_link4_est">
    <material>Gazebo/White</material>
    <gravity>false</gravity>
    <sensor name="imu_sensor4_est" type="imu">
      <always_on>true</always_on>
      <update_rate>100</update_rate>
      <visualize>true</visualize>
      <topic>imu_data4_est</topic>
      <plugin filename="libgazebo_ros_imu_sensor.so" name="imu_plugin">
        <topicName>imu_data4_est</topicName>
        <bodyName>imu_link4_est</bodyName>
        <updateRateHZ>100.0</updateRateHZ>
        <gaussianNoise>0.0</gaussianNoise>
        <xyzOffset>0.0 0.0 0.0</xyzOffset>
        <rpyOffset>0 0 0</rpyOffset>
        <frameName>imu_link4_est</frameName>
      </plugin>
      <pose>0 0 0 0 0 0</pose>
    </sensor>
  </gazebo>
  <joint name="imu_to_world5_est" type="floating">
    <parent link="world"/>
    <child link="imu_link5_est"/>
    <!-- XYZ, RPY from parent Visual Origin (Center o Gravity) -->
    <!-- in this case it's 0 0 0-->
    <origin rpy="0 0 0" xyz="0 0 0"/>
  </joint>
  <link name="imu_link5_est">
    <inertial>
      <origin rpy="0 0 0" xyz="0 0 0.005"/>
      <mass value="0.01"/>
      <inertia ixx="0.0" ixy="0.0" ixz="0.0" iyy="0.0" iyz="0.0" izz="0.0"/>
    </inertial>
    <visual>
      <origin rpy="0 0 0" xyz="0 0 0.005"/>
      <geometry>
        <box size="0.02 0.02 0.01"/>
      </geometry>
    </visual>
  </link>
  <gazebo reference="imu_link5_est">
    <material>Gazebo/White</material>
    <gravity>false</gravity>
    <sensor name="imu_sensor5_est" type="imu">
      <always_on>true</always_on>
      <update_rate>100</update_rate>
      <visualize>true</visualize>
      <topic>imu_data5_est</topic>
      <plugin filename="libgazebo_ros_imu_sensor.so" name="imu_plugin">
        <topicName>imu_data5_est</topicName>
        <bodyName>imu_link5_est</bodyName>
        <updateRateHZ>100.0</updateRateHZ>
        <gaussianNoise>0.0</gaussianNoise>
        <xyzOffset>0.0 0.0 0.0</xyzOffset>
        <rpyOffset>0 0 0</rpyOffset>
        <frameName>imu_link5_est</frameName>
      </plugin>
      <pose>0 0 0 0 0 0</pose>
    </sensor>
  </gazebo>
  <joint name="imu_to_world6_est" type="floating">
    <parent link="world"/>
    <child link="imu_link6_est"/>
    <!-- XYZ, RPY from parent Visual Origin (Center o Gravity) -->
    <!-- in this case it's 0 0 0-->
    <origin rpy="0 0 0" xyz="0 0 0"/>
  </joint>
  <link name="imu_link6_est">
    <inertial>
      <origin rpy="0 0 0" xyz="0 0 0.005"/>
      <mass value="0.01"/>
      <inertia ixx="0.0" ixy="0.0" ixz="0.0" iyy="0.0" iyz="0.0" izz="0.0"/>
    </inertial>
    <visual>
      <origin rpy="0 0 0" xyz="0 0 0.005"/>
      <geometry>
        <box size="0.02 0.02 0.01"/>
      </geometry>
    </visual>
  </link>
  <gazebo reference="imu_link6_est">
    <material>Gazebo/White</material>
    <gravity>false</gravity>
    <sensor name="imu_sensor6_est" type="imu">
      <always_on>true</always_on>
      <update_rate>100</update_rate>
      <visualize>true</visualize>
      <topic>imu_data6_est</topic>
      <plugin filename="libgazebo_ros_imu_sensor.so" name="imu_plugin">
        <topicName>imu_data6_est</topicName>
        <bodyName>imu_link6_est</bodyName>
        <updateRateHZ>100.0</updateRateHZ>
        <gaussianNoise>0.0</gaussianNoise>
        <xyzOffset>0.0 0.0 0.0</xyzOffset>
        <rpyOffset>0 0 0</rpyOffset>
        <frameName>imu_link6_est</frameName>
      </plugin>
      <pose>0 0 0 0 0 0</pose>
    </sensor>
  </gazebo>
  <gazebo>
    <static>true</static>
  </gazebo>
</robot>
